Workbook

Sheet Instrucciones
B1: Base de relevamiento · Corredor Bioceánico (Jujuy)
B2: Planilla que recibe los datos de la app de campo y arma el tablero sola.
B4: Hojas
B5: Tablero: indicadores, tablas y gráficos. Se recalcula solo; las únicas celdas para escribir son las amarillas (nombres de equipos).
B6: Datos: una fila por relevamiento. La llena el script o se pega el CSV de la app. No cambiar la fila 1 ni insertar columnas en el medio.
B7: Contactos: correo y celular. Datos personales: proteger la hoja y no compartirla.
B8: Diccionario: qué significa cada columna, sus valores posibles y un ejemplo.
B10: Opción 1 — Planilla de Google (recomendada, sin costo)
B11: 1. Subí este archivo al Drive de la cuenta de Gmail del proyecto y abrilo con Hojas de cálculo de Google (Archivo > Guardar como Hojas de cálculo de Google).
B12: 2. En esa planilla: Extensiones > Apps Script. Borrá lo que aparece, pegá el contenido de Codigo.gs y cambiá la clave de la línea TOKEN.
B13: 3. Implementar > Nueva implementación > tipo «Aplicación web». Ejecutar como: Yo. Quién tiene acceso: Cualquier usuario. Autorizá los permisos.
B14: 4. Copiá la URL que termina en /exec y pegala, junto con la clave, en Ajustes de cada celular. Tocá «Probar conexión».
... B28: Las preguntas de opción múltiple se guardan separadas por «; » (por ejemplo: «Español; Portugués»).

Sheet Tablero
B1: Tablero · Conductores de camiones del Corredor Bioceánico (Jujuy)
B2: DATOS FICTICIOS DE EJEMPLO. Para usar la planilla real, partí de Base_Relevamiento_Tablero.xlsx.
B4: Indicadores generales
B5: Indicador | C5: Valor
B6: Relevamientos recibidos | C6: =COUNTA(Datos!$A$2:$A$3000)
B7: Participantes únicos (por ID) | C7: =IFERROR(SUMPRODUCT((Datos!$B$2:$B$3000<>"")/COUNTIF(Datos!$B$2:$B$3000,Datos!$B$2:$B$3000&"")),0)
B8: Relevamientos finalizados | C8: =COUNTIF(Datos!$T$2:$T$3000,"finalizado")
B9: Con sociodemográfica completa | C9: =COUNTIF(Datos!$Q$2:$Q$3000,"Sí")
B10: Con biológica completa | C10: =COUNTIF(Datos!$R$2:$R$3000,"Sí")
B11: Con glucometría realizada | C11: =COUNTIF(Datos!$S$2:$S$3000,"Sí")
B12: Primer relevamiento | C12: =IF(COUNT(Datos!$G$2:$G$3000)=0,"",MIN(Datos!$G$2:$G$3000))
B13: Último relevamiento | C13: =IF(COUNT(Datos!$G$2:$G$3000)=0,"",MAX(Datos!$G$2:$G$3000))
B15: Avance por equipo
B16: Las celdas amarillas son editables: escribí la letra de cada equipo tal como se cargó en Ajustes.
B17: Equipo | C17: Relevamientos | D17: Finalizados | E17: Con biológica | F17: Último
B18: A | C18: =IF(B18="","",COUNTIF(Datos!$J$2:$J$3000,B18)) | D18: =IF(B18="","",COUNTIFS(Datos!$J$2:$J$3000,B18,Datos!$T$2:$T$3000,"finalizado")) | E18: =IF(B18="","",COUNTIFS(Datos!$J$2:$J$3000,B18,Datos!$R$2:$R$3000,"Sí")) | F18: =IF(OR(B18="",COUNTIF(Datos!$J$2:$J$3000,B18)=0),"",_xlfn.MAXIFS(Datos!$G$2:$G$3000,Datos!$J$2:$J$3000,B18))
B19: B | C19: =IF(B19="","",COUNTIF(Datos!$J$2:$J$3000,B19)) | D19: =IF(B19="","",COUNTIFS(Datos!$J$2:$J$3000,B19,Datos!$T$2:$T$3000,"finalizado")) | E19: =IF(B19="","",COUNTIFS(Datos!$J$2:$J$3000,B19,Datos!$R$2:$R$3000,"Sí")) | F19: =IF(OR(B19="",COUNTIF(Datos!$J$2:$J$3000,B19)=0),"",_xlfn.MAXIFS(Datos!$G$2:$G$3000,Datos!$J$2:$J$3000,B19))
B20: C | C20: =IF(B20="","",COUNTIF(Datos!$J$2:$J$3000,B20)) | D20: =IF(B20="","",COUNTIFS(Datos!$J$2:$J$3000,B20,Datos!$T$2:$T$3000,"finalizado")) | E20: =IF(B20="","",COUNTIFS(Datos!$J$2:$J$3000,B20,Datos!$R$2:$R$3000,"Sí")) | F20: =IF(OR(B20="",COUNTIF(Datos!$J$2:$J$3000,B20)=0),"",_xlfn.MAXIFS(Datos!$G$2:$G$3000,Datos!$J$2:$J$3000,B20))
B21: D | C21: =IF(B21="","",COUNTIF(Datos!$J$2:$J$3000,B21)) | D21: =IF(B21="","",COUNTIFS(Datos!$J$2:$J$3000,B21,Datos!$T$2:$T$3000,"finalizado")) | E21: =IF(B21="","",COUNTIFS(Datos!$J$2:$J$3000,B21,Datos!$R$2:$R$3000,"Sí")) | F21: =IF(OR(B21="",COUNTIF(Datos!$J$2:$J$3000,B21)=0),"",_xlfn.MAXIFS(Datos!$G$2:$G$3000,Datos!$J$2:$J$3000,B21))
B22: E | C22: =IF(B22="","",COUNTIF(Datos!$J$2:$J$3000,B22)) | D22: =IF(B22="","",COUNTIFS(Datos!$J$2:$J$3000,B22,Datos!$T$2:$T$3000,"finalizado")) | E22: =IF(B22="","",COUNTIFS(Datos!$J$2:$J$3000,B22,Datos!$R$2:$R$3000,"Sí")) | F22: =IF(OR(B22="",COUNTIF(Datos!$J$2:$J$3000,B22)=0),"",_xlfn.MAXIFS(Datos!$G$2:$G$3000,Datos!$J$2:$J$3000,B22))
B24: Promedios
B25: La glucemia promedia mediciones con distintos tiempos de ayuno: usarla solo como referencia.
B26: Variable | C26: Total | D26: Varón | E26: Mujer | F26: n
B27: Edad (años) | C27: =IFERROR(AVERAGE(Datos!$E$2:$E$3000),"") | D27: =IFERROR(AVERAGEIFS(Datos!$E$2:$E$3000,Datos!$BX$2:$BX$3000,"Varón"),"") | E27: =IFERROR(AVERAGEIFS(Datos!$E$2:$E$3000,Datos!$BX$2:$BX$3000,"Mujer"),"") | F27: =COUNT(Datos!$E$2:$E$3000)
B28: IMC (kg/m²) | C28: =IFERROR(AVERAGE(Datos!$CA$2:$CA$3000),"") | D28: =IFERROR(AVERAGEIFS(Datos!$CA$2:$CA$3000,Datos!$BX$2:$BX$3000,"Varón"),"") | E28: =IFERROR(AVERAGEIFS(Datos!$CA$2:$CA$3000,Datos!$BX$2:$BX$3000,"Mujer"),"") | F28: =COUNT(Datos!$CA$2:$CA$3000)
B29: Perímetro abdominal (cm) | C29: =IFERROR(AVERAGE(Datos!$CB$2:$CB$3000),"") | D29: =IFERROR(AVERAGEIFS(Datos!$CB$2:$CB$3000,Datos!$BX$2:$BX$3000,"Varón"),"") | E29: =IFERROR(AVERAGEIFS(Datos!$CB$2:$CB$3000,Datos!$BX$2:$BX$3000,"Mujer"),"") | F29: =COUNT(Datos!$CB$2:$CB$3000)
B30: Presión sistólica (mmHg) | C30: =IFERROR(AVERAGE(Datos!$CC$2:$CC$3000),"") | D30: =IFERROR(AVERAGEIFS(Datos!$CC$2:$CC$3000,Datos!$BX$2:$BX$3000,"Varón"),"") | E30: =IFERROR(AVERAGEIFS(Datos!$CC$2:$CC$3000,Datos!$BX$2:$BX$3000,"Mujer"),"") | F30: =COUNT(Datos!$CC$2:$CC$3000)
B31: Glucemia periférica (mg/dL) | C31: =IFERROR(AVERAGE(Datos!$CP$2:$CP$3000),"") | D31: =IFERROR(AVERAGEIFS(Datos!$CP$2:$CP$3000,Datos!$BX$2:$BX$3000,"Varón"),"") | E31: =IFERROR(AVERAGEIFS(Datos!$CP$2:$CP$3000,Datos!$BX$2:$BX$3000,"Mujer"),"") | F31: =COUNT(Datos!$CP$2:$CP$3000)
B32: Años como chofer | C32: =IFERROR(AVERAGE(Datos!$AJ$2:$AJ$3000),"") | D32: =IFERROR(AVERAGEIFS(Datos!$AJ$2:$AJ$3000,Datos!$BX$2:$BX$3000,"Varón"),"") | E32: =IFERROR(AVERAGEIFS(Datos!$AJ$2:$AJ$3000,Datos!$BX$2:$BX$3000,"Mujer"),"") | F32: =COUNT(Datos!$AJ$2:$AJ$3000)
B33: Horas de conducción sin paradas | C33: =IFERROR(AVERAGE(Datos!$AT$2:$AT$3000),"") | D33: =IFERROR(AVERAGEIFS(Datos!$AT$2:$AT$3000,Datos!$BX$2:$BX$3000,"Varón"),"") | E33: =IFERROR(AVERAGEIFS(Datos!$AT$2:$AT$3000,Datos!$BX$2:$BX$3000,"Mujer"),"") | F33: =COUNT(Datos!$AT$2:$AT$3000)
B34: Horas de sueño por día | C34: =IFERROR(AVERAGE(Datos!$AX$2:$AX$3000),"") | D34: =IFERROR(AVERAGEIFS(Datos!$AX$2:$AX$3000,Datos!$BX$2:$BX$3000,"Varón"),"") | E34: =IFERROR(AVERAGEIFS(Datos!$AX$2:$AX$3000,Datos!$BX$2:$BX$3000,"Mujer"),"") | F34: =COUNT(Datos!$AX$2:$AX$3000)
B36: Riesgo de diabetes a 10 años (FINDRISK)
B37: Solo personas sin diagnóstico de diabetes y con sexo mujer o varón.
B38: Categoría | C38: n | D38: % | E38: Varón (n) | F38: Mujer (n)
B39: Bajo | C39: =COUNTIF(Datos!$CT$2:$CT$3000,"Bajo") | D39: =IF($C$44=0,"",C39/$C$44) | E39: =COUNTIFS(Datos!$CT$2:$CT$3000,"Bajo",Datos!$BX$2:$BX$3000,"Varón") | F39: =COUNTIFS(Datos!$CT$2:$CT$3000,"Bajo",Datos!$BX$2:$BX$3000,"Mujer")
B40: Ligeramente elevado | C40: =COUNTIF(Datos!$CT$2:$CT$3000,"Ligeramente elevado") | D40: =IF($C$44=0,"",C40/$C$44) | E40: =COUNTIFS(Datos!$CT$2:$CT$3000,"Ligeramente elevado",Datos!$BX$2:$BX$3000,"Varón") | F40: =COUNTIFS(Datos!$CT$2:$CT$3000,"Ligeramente elevado",Datos!$BX$2:$BX$3000,"Mujer")
B41: Moderado | C41: =COUNTIF(Datos!$CT$2:$CT$3000,"Moderado") | D41: =IF($C$44=0,"",C41/$C$44) | E41: =COUNTIFS(Datos!$CT$2:$CT$3000,"Moderado",Datos!$BX$2:$BX$3000,"Varón") | F41: =COUNTIFS(Datos!$CT$2:$CT$3000,"Moderado",Datos!$BX$2:$BX$3000,"Mujer")
B42: Alto | C42: =COUNTIF(Datos!$CT$2:$CT$3000,"Alto") | D42: =IF($C$44=0,"",C42/$C$44) | E42: =COUNTIFS(Datos!$CT$2:$CT$3000,"Alto",Datos!$BX$2:$BX$3000,"Varón") | F42: =COUNTIFS(Datos!$CT$2:$CT$3000,"Alto",Datos!$BX$2:$BX$3000,"Mujer")
B43: Muy alto | C43: =COUNTIF(Datos!$CT$2:$CT$3000,"Muy alto") | D43: =IF($C$44=0,"",C43/$C$44) | E43: =COUNTIFS(Datos!$CT$2:$CT$3000,"Muy alto",Datos!$BX$2:$BX$3000,"Varón") | F43: =COUNTIFS(Datos!$CT$2:$CT$3000,"Muy alto",Datos!$BX$2:$BX$3000,"Mujer")
B44: Respondieron | C44: =COUNTA(Datos!$CT$2:$CT$3000) | E44: =SUM(E39:E43) | F44: =SUM(F39:F43)
...

Sheet Datos
A1: id | B1: participante_id | C1: codigo | D1: orden | E1: edad | F1: cp | G1: fecha | H1: hora_inicio | I1: hora_fin | J1: equipo | K1: dispositivo | L1: encuestador | M1: puesto | N1: consentimiento | O1: comparte_app | P1: socio_respondidas | Q1: socio_completo | R1: bio_completo | S1: gluc_realizada | T1: estado | U1: version_instrumento | V1: modificado | W1: p01_nac_pais | X1: p01_nac_detalle | Y1: p02_educacion | Z1: p03_pareja | AA1: p04_convive | AB1: p05_a_cargo | AC1: p06_idiomas_entiende | AD1: p06_otro | AE1: p07_idiomas_habla | AF1: p07_otro | AG1: p08_licencia | AH1: p08_lic_otro | AI1: p09_rutas_jujuy | AJ1: p10_anios_chofer | AK1: p11_recorrido | AL1: p12_frec_corredor | AM1: p12_frec_corredor_otro | AN1: p12_frec_jujuy | AO1: p12_frec_jujuy_otro | AP1: p13_relacion_laboral | AQ1: p13_otro | AR1: p14_conformidad | AS1: p15_riesgo_salud | AT1: p16_horas_sin_parar | AU1: p17_paradas | AV1: p18_donde_come | AW1: p18_otro | AX1: p19_horas_sueno | AY1: p20_frutas_verduras | AZ1: p21_bebidas | BA1: p21_otro | BB1: p22_sanitarios | BC1: p23_recreativas | BD1: p24_siniestro | BE1: p25_fin_de_mes | BF1: p26_cobertura | BG1: p27_control_medico | BH1: p28_frec_consulta | BI1: p29_atencion_dolencias | BJ1: p30_dolores | BK1: p30_cuales | BL1: p31_automedicacion | BM1: p32_cuales_med | BN1: p33_diagnosticos | BO1: p33_otro | BP1: p34_actividad_fisica | BQ1: p35_energeticas | BR1: p35_otro | BS1: p36_coquea | BT1: p37_alcohol | BU1: p38_comunicacion | BV1: p39_comparte_trayectos | BW1: b_dbt_dx | BX1: b_sexo | BY1: b_peso_kg | BZ1: b_altura_m | CA1: b_imc | CB1: b_perimetro_cm | CC1: b_pas_mmhg | CD1: b_pad_mmhg | CE1: b_act_fisica | CF1: b_fyv_diario | CG1: b_hta_dx | CH1: b_med_antihta | CI1: b_glucosa_previa | CJ1: b_antec_fam_dbt | CK1: b_fuma | CL1: g_acepta | CM1: g_hora_ingesta | CN1: g_que_ingirio | CO1: g_hora_medicion | CP1: g_resultado_mgdl | CQ1: g_ayuno_min | CR1: fr_aplica | CS1: fr_puntos | CT1: fr_categoria | CU1: fr_probabilidad | CV1: fh_aplica | CW1: fh_puntos | CX1: fh_riesgo | CY1: fh_categoria
A2: demo-1 | B2: B1-0001 | C2: 200-63-4630 | D2: 200 | E2: 63 | F2: 4630 | G2: 46290 | H2: 10:08 | J2: B | K2: 1 | L2: Encuestador B | M2: Puesto 2 | N2: Sí | O2: No | P2: 38 | Q2: Sí | R2: No | S2: No | T2: finalizado | U2: 2026-10-v2 | V2: 2026-09-25T15:00:00.000Z | W2: Chile | Y2: Secundaria incompleta | Z2: Sí | AA2: Más de 5 | AB2: 3 | AC2: Inglés; Portugués | AE2: Español | AG2: Argentina | AI2: Regular | AJ2: 6 | AK2: Viaje interprovincial | AL2: Una vez al mes | AN2: Diariamente | AP2: Empleado | AR2: Disconforme | AS2: Sí | AT2: 6.7 | AU2: Sí | AV2: Estaciones de servicio | AX2: 5.7 | AY2: Todos los días | AZ2: Jugos artificiales; Gaseosas | BB2: Sí, siempre | BC2: Sí | BD2: Sí | BE2: No | BF2: Obra social | BG2: Sistema público | BH2: 2 veces al año | BI2: Sistema público; Otros (medicina tradicional, alternativa, etc.) | BJ2: No | BL2: Ninguno | BN2: Musculoesqueléticos | BP2: Rara vez | BQ2: Café | BS2: No | BT2: Sí | BU2: A veces | BV2: Sí
A3: demo-2 | B3: B1-0002 | C3: 201-47-4400 | D3: 201 | E3: 47 | F3: 4400 | G3: 46302 | H3: 14:09 | J3: B | K3: 1 | L3: Encuestador B | M3: Puesto 1 | N3: Sí | O3: Sí | P3: 39 | Q3: Sí | R3: Sí | S3: Sí | T3: finalizado | U3: 2026-10-v2 | V3: 2026-10-07T15:00:00.000Z | W3: Argentina | Y3: Secundaria completa | Z3: No | AA3: 1 | AB3: 3 | AC3: Guaraní | AE3: Español | AG3: Argentina | AI3: Regular | AJ3: 19 | AK3: Viaje provincial (Jujuy) | AL3: Una vez a la semana | AN3: 2 veces por semana | AP3: Empleado | AR3: Disconforme | AS3: Sí | AT3: 2.2 | AU3: Sí | AV3: En el camión al costado de la ruta | AX3: 5.7 | AY3: Varias veces por semana | AZ3: Café; Mate | BB3: Casi nunca | BC3: Sí | BD3: Sí | BE3: Parcialmente | BF3: Obra social | BG3: Sistema público | BH3: Nunca | BI3: Sistema público; Otros (medicina tradicional, alternativa, etc.) | BJ3: Sí | BK3: Cervical | BL3: Medicamentos | BM3: Ibuprofeno | BN3: No tengo diagnóstico de enfermedad | BP3: Una vez a la semana | BQ3: Café | BS3: Sí | BT3: Sí | BU3: A veces | BV3: No | BW3: No | BX3: Varón | BY3: 91.7 | BZ3: 1.74 | CA3: 30.3 | CB3: 97 | CC3: 155 | CD3: 98 | CE3: No | CF3: No | CG3: No | CH3: No | CI3: Sí | CJ3: No | CK3: Sí | CL3: Sí | CM3: 07:40 | CN3: Mate | CO3: 11:30 | CP3: 100 | CQ3: 230 | CR3: Sí | CS3: 16 | CT3: Alto | CU3: 33 % | CV3: Sí | CW3: 11 | CX3: 8 | CY3: Bajo
A4: demo-3 | B4: C1-0003 | C4: 402-61-4400 | D4: 402 | E4: 61 | F4: 4400 | G4: 46302 | H4: 16:08 | J4: C | K4: 1 | L4: Encuestador C | M4: Puesto 1 | N4: Sí | O4: Sí | P4: 39 | Q4: Sí | R4: Sí | S4: Sí | T4: finalizado | U4: 2026-10-v2 | V4: 2026-10-07T15:00:00.000Z | W4: Argentina | Y4: Universitario incompleto | Z4: Sí | AA4: 4 | AB4: Más de 5 | AC4: Inglés | AE4: Español | AG4: Argentina | AI4: Regular | AJ4: 5 | AK4: Viaje internacional | AL4: Una vez a la semana | AN4: Una vez a la semana | AP4: Empleado | AR4: Disconforme | AS4: Sí | AT4: 4 | AU4: Sí | AV4: En el camión al costado de la ruta | AX4: 6.5 | AY4: Todos los días | AZ4: Jugos artificiales; Café; Agua | BB4: Sí, siempre | BC4: Algunas veces | BD4: No | BE4: Parcialmente | BF4: Obra social | BG4: Sistema público | BH4: 2 veces al año | BI4: Sistema privado | BJ4: Sí | BK4: Cervical | BL4: Medicamentos | BM4: Ibuprofeno | BN4: No tengo diagnóstico de enfermedad | BP4: Rara vez | BQ4: Energizantes (Speed, Monster, Red Bull, etc.) | BS4: Sí | BT4: Sí | BU4: Nunca | BV4: Sí | BW4: No | BX4: Varón | BY4: 85.9 | BZ4: 1.88 | CA4: 24.3 | CB4: 107 | CC4: 109 | CD4: 70 | CE4: No | CF4: Sí | CG4: No | CH4: Sí | CI4: No | CJ4: No | CK4: Sí | CL4: Sí | CM4: 07:24 | CN4: Mate | CO4: 13:30 | CP4: 87 | CQ4: 366 | CR4: Sí | CS4: 11 | CT4: Ligeramente elevado | CU4: 4 % | CV4: Sí | CW4: 11 | CX4: 8 | CY4: Bajo
A5: demo-4 | B5: A1-0004 | C5: 004-37-4612 | D5: 4 | E5: 37 | F5: 4612 | G5: 46290 | H5: 12:09 | J5: A | K5: 1 | L5: Encuestador A | M5: Puesto 1 | N5: Sí | O5: Sí | P5: 39 | Q5: Sí | R5: Sí | S5: Sí | T5: finalizado | U5: 2026-10-v2 | V5: 2026-09-25T15:00:00.000Z | W5: Argentina | Y5: Secundaria incompleta | Z5: Sí | AA5: 1 | AB5: 2 | AC5: Guaraní; Español | AE5: Español | AG5: Argentina | AI5: Regular | AJ5: 2 | AK5: Viaje interprovincial | AL5: Quincenalmente | AN5: 3 veces por semana | AP5: Empleado | AR5: Disconforme | AS5: Sí | AT5: 8.8 | AU5: Sí | AV5: Estaciones de servicio; Paradores | AX5: 6.1 | AY5: Casi nunca | AZ5: Gaseosas; Café | BB5: Nunca | BC5: No | BD5: No | BE5: Parcialmente | BF5: Obra social | BG5: Sistema privado | BH5: Una vez al año | BI5: Sistema público; Otros (medicina tradicional, alternativa, etc.) | BJ5: No | BL5: Medicamentos | BM5: Ibuprofeno | BN5: Musculoesqueléticos; Digestivas | BP5: Rara vez | BQ5: Café | BS5: No | BT5: No | BU5: A veces | BV5: No | BW5: No | BX5: Varón | BY5: 69.4 | BZ5: 1.7 | CA5: 24 | CB5: 82 | CC5: 138 | CD5: 88 | CE5: No | CF5: Sí | CG5: No | CH5: No | CI5: No | CJ5: No | CK5: Sí | CL5: Sí | CM5: 07:47 | CN5: Mate | CO5: 12:30 | CP5: 181 | CQ5: 283 | CR5: Sí | CS5: 2 | CT5: Bajo | CU5: 1 % | CV5: Sí | CW5: 5 | CX5: 2 | CY5: Bajo
A6: demo-5 | B6: C1-0005 | C6: 404-59-4600 | D6: 404 | E6: 59 | F6: 4600 | G6: 46294 | H6: 14:02 | J6: C | K6: 1 | L6: Encuestador C | M6: Puesto 2 | N6: Sí | O6: No | P6: 39 | Q6: Sí | R6: Sí | S6: Sí | T6: borrador | U6: 2026-10-v2 | V6: 2026-09-29T15:00:00.000Z | W6: Argentina | Y6: Primaria completa | Z6: Sí | AA6: 3 | AB6: 1 | AC6: Portugués | AE6: Español | AG6: Argentina | AI6: Malo | AJ6: 25 | AK6: Viaje interprovincial | AL6: Quincenalmente | AN6: 3 veces por semana | AP6: Otro | AR6: Parcialmente conforme | AS6: Sí | AT6: 4.7 | AU6: Sí | AV6: Paradores; Estaciones de servicio | AX6: 7.7 | AY6: Todos los días | AZ6: Agua; Jugos artificiales; Café | BB6: Nunca | BC6: No | BD6: No | BE6: Parcialmente | BF6: Obra social | BG6: Sistema público | BH6: Una vez al año | BI6: Sistema privado | BJ6: No | BL6: Medicamentos; Hierbas | BM6: Ibuprofeno | BN6: Musculoesqueléticos; Digestivas | BP6: Una vez a la semana | BQ6: Café | BS6: Sí | BT6: Sí | BU6: A veces | BV6: Sí | BW6: No | BX6: Varón | BY6: 88.2 | BZ6: 1.65 | CA6: 32.4 | CB6: 107 | CC6: 132 | CD6: 84 | CE6: No | CF6: Sí | CG6: Sí | CH6: No | CI6: No | CJ6: No | CK6: Sí | CL6: Sí | CM6: 07:27 | CN6: Mate | CO6: 12:30 | CP6: 131 | CQ6: 303 | CR6: Sí | CS6: 12 | CT6: Moderado | CU6: 17 % | CV6: Sí | CW6: 14 | CX6: 16 | CY6: Moderado
A7: demo-6 | B7: C1-0006 | C7: 405-58-4630 | D7: 405 | E7: 58 | F7: 4630 | G7: 46302 | H7: 10:07 | J7: C | K7: 1 | L7: Encuestador C | M7: Puesto 2 | N7: Sí | O7: No | P7: 38 | Q7: Sí | R7: Sí | S7: Sí | T7: finalizado | U7: 2026-10-v2 | V7: 2026-10-07T15:00:00.000Z | W7: Argentina | Y7: Secundaria incompleta | Z7: No | AA7: Más de 5 | AB7: 2 | AC7: Inglés | AE7: Español | AG7: Argentina | AI7: Malo | AJ7: 21 | AK7: Viaje interprovincial | AL7: 2 veces por semana | AN7: 3 veces por semana | AP7: Dueño del camión | AR7: Disconforme | AS7: Sí | AT7: 4.2 | AU7: Sí | AV7: En el camión al costado de la ruta | AX7: 7.3 | AY7: Todos los días | AZ7: Agua; Gaseosas | BB7: Casi nunca | BC7: Algunas veces | BD7: No | BE7: Sí | BF7: Obra social; Prepaga | BG7: Sistema público | BH7: Solo cuando me siento mal | BI7: Sistema público; Otros (medicina tradicional, alternativa, etc.) | BJ7: Sí | BK7: Cervical | BL7: Ninguno | BN7: Musculoesqueléticos; Digestivas | BP7: Nunca | BQ7: Café; Coca-Cola | BS7: No | BT7: No | BU7: Siempre | BV7: Sí | BW7: No | BX7: Varón | BY7: 77.8 | BZ7: 1.72 | CA7: 26.3 | CB7: 104 | CC7: 153 | CD7: 97 | CE7: No | CF7: No | CG7: Sí | CH7: Sí | CI7: No | CJ7: Sí, primer grado | CK7: Sí | CL7: Sí | CM7: 07:34 | CN7: Mate | CO7: 13:30 | CP7: 116 | CQ7: 356 | CR7: Sí | CS7: 18 | CT7: Alto | CU7: 33 % | CV7: Sí | CW7: 14 | CX7: 16 | CY7: Moderado
A8: demo-7 | B8: C1-0007 | C8: 406-41-4630 | D8: 406 | E8: 41 | F8: 4630 | G8: 46291 | H8: 16:00 | J8: C | K8: 1 | L8: Encuestador C | M8: Puesto 1 | N8: Sí | O8: Sí | P8: 39 | Q8: Sí | R8: Sí | S8: No | T8: finalizado | U8: 2026-10-v2 | V8: 2026-09-26T15:00:00.000Z | W8: Argentina | Y8: Secundaria completa | Z8: Sí | AA8: 4 | AB8: 3 | AC8: Inglés | AE8: Español | AG8: Argentina | AI8: Regular | AJ8: 10 | AK8: Viaje interprovincial | AL8: Una vez al mes | AN8: Diariamente | AP8: Empleado | AR8: Disconforme | AS8: Sí | AT8: 5.9 | AU8: Sí | AV8: Estaciones de servicio | AX8: 5.4 | AY8: Casi nunca | AZ8: Jugos artificiales | BB8: Sí, siempre | BC8: Algunas veces | BD8: No | BE8: Sí | BF8: Obra social | BG8: Ninguno | BH8: Una vez al año | BI8: Sistema público; Otros (medicina tradicional, alternativa, etc.) | BJ8: No | BL8: Medicamentos | BM8: Ibuprofeno | BN8: Musculoesqueléticos | BP8: 2 a 3 veces por semana | BQ8: Café | BS8: Sí | BT8: No | BU8: Siempre | BV8: No | BW8: No | BX8: Varón | BY8: 78.3 | BZ8: 1.77 | CA8: 25 | CB8: 88 | CC8: 134 | CD8: 85 | CE8: Sí | CF8: Sí | CG8: No | CH8: No | CI8: No | CJ8: No | CK8: Sí | CL8: No | CR8: Sí | CS8: 1 | CT8: Bajo | CU8: 1 % | CV8: Sí | CW8: 7 | CX8: 3 | CY8: Bajo
A9: demo-8 | B9: C1-0008 | C9: 407-51-4500 | D9: 407 | E9: 51 | F9: 4500 | G9: 46296 | H9: 12:02 | J9: C | K9: 1 | L9: Encuestador C | M9: Puesto 1 | N9: Sí | O9: Sí | P9: 38 | Q9: Sí | R9: Sí | S9: Sí | T9: finalizado | U9: 2026-10-v2 | V9: 2026-10-01T15:00:00.000Z | W9: Brasil | Y9: Secundaria completa | Z9: Sí | AA9: 4 | AB9: 5 | AC9: Inglés | AE9: Español | AG9: Argentina | AI9: Malo | AJ9: 13 | AK9: Viaje internacional | AL9: Quincenalmente | AN9: Diariamente | AP9: Otro | AR9: Disconforme | AS9: Sí | AT9: 3.9 | AU9: Sí | AV9: Paradores | AX9: 5.1 | AY9: Todos los días | AZ9: Jugos artificiales | BB9: A veces | BC9: Rara vez | BD9: No | BE9: Sí | BF9: Ninguna | BG9: Sistema privado | BH9: Nunca | BI9: Sistema privado | BJ9: No | BL9: Ninguno | BN9: No tengo diagnóstico de enfermedad | BP9: Una vez a la semana | BQ9: Café; Coca-Cola | BS9: Sí | BT9: Sí | BU9: Nunca | BV9: No | BW9: No | BX9: Varón | BY9: 76.4 | BZ9: 1.78 | CA9: 24.1 | CB9: 89 | CC9: 141 | CD9: 89 | CE9: Sí | CF9: No | CG9: No | CH9: No | CI9: No | CJ9: No | CK9: No | CL9: Sí | CM9: 07:47 | CN9: Mate | CO9: 11:30 | CP9: 180 | CQ9: 223 | CR9: Sí | CS9: 3 | CT9: Bajo | CU9: 1 % | CV9: Sí | CW9: 7 | CX9: 3 | CY9: Bajo
A10: demo-9 | B10: A1-0009 | C10: 009-43-4630 | D10: 9 | E10: 43 | F10: 4630 | G10: 46295 | H10: 13:05 | J10: A | K10: 1 | L10: Encuestador A | M10: Puesto 2 | N10: Sí | O10: Sí | P10: 39 | Q10: Sí | R10: Sí | S10: No | T10: finalizado | U10: 2026-10-v2 | V10: 2026-09-30T15:00:00.000Z | W10: Argentina | Y10: Universitario completo | Z10: Sí | AA10: 2 | AB10: 2 | AC10: Español | AE10: Español | AG10: Argentina | AI10: Regular | AJ10: 1 | AK10: Viaje internacional | AL10: Una vez a la semana | AN10: Una vez a la semana | AP10: Dueño del camión | AR10: Disconforme | AS10: Sí | AT10: 2.1 | AU10: Sí | AV10: Paradores | AX10: 6.7 | AY10: Varias veces por semana | AZ10: Agua; Mate | BB10: A veces | BC10: No | BD10: No | BE10: No | BF10: Obra social | BG10: Sistema público | BH10: Solo cuando me siento mal | BI10: Sistema público | BJ10: Sí | BK10: Lumbar | BL10: Medicamentos | BM10: Ibuprofeno | BN10: No tengo diagnóstico de enfermedad | BP10: Una vez a la semana | BQ10: Café | BS10: Sí | BT10: Sí | BU10: Nunca | BV10: Sí | BW10: No | BX10: Varón | BY10: 98.1 | BZ10: 1.83 | CA10: 29.3 | CB10: 115 | CC10: 123 | CD10: 78 | CE10: No | CF10: Sí | CG10: No | CH10: No | CI10: Sí | CJ10: No | CK10: Sí | CL10: No | CR10: Sí | CS10: 12 | CT10: Moderado | CU10: 17 % | CV10: Sí | CW10: 6 | CX10: 2 | CY10: Bajo
A11: demo-10 | B11: C1-0010 | C11: 409-44-4600 | D11: 409 | E11: 44 | F11: 4600 | G11: 46296 | H11: 16:08 | J11: C | K11: 1 | L11: Encuestador C | M11: Puesto 2 | N11: Sí | O11: Sí | P11: 39 | Q11: Sí | R11: Sí | S11: Sí | T11: finalizado | U11: 2026-10-v2 | V11: 2026-10-01T15:00:00.000Z | W11: Argentina | Y11: Terciario incompleto | Z11: Sí | AA11: Más de 5 | AB11: 5 | AC11: Guaraní | AE11: Español | AG11: Argentina | AI11: Bueno | AJ11: 4 | AK11: Viaje provincial (Jujuy) | AL11: Una vez a la semana | AN11: Una vez a la semana | AP11: Dueño del camión | AR11: Parcialmente conforme | AS11: Sí | AT11: 3.6 | AU11: Sí | AV11: Paradores; En el camión al costado de la ruta | AX11: 6.2 | AY11: Nunca | AZ11: Mate; Gaseosas | BB11: Nunca | BC11: No | BD11: Sí | BE11: No | BF11: Seguro de salud | BG11: Ninguno | BH11: Solo cuando me siento mal | BI11: Sistema privado | BJ11: Sí | BK11: Cervical | BL11: Medicamentos | BM11: Ibuprofeno | BN11: Musculoesqueléticos | BP11: Nunca | BQ11: Yerba mate | BS11: Sí | BT11: Sí | BU11: Siempre | BV11: No | BW11: No | BX11: Varón | BY11: 88 | BZ11: 1.88 | CA11: 24.9 | CB11: 106 | CC11: 142 | CD11: 90 | CE11: No | CF11: No | CG11: No | CH11: No | CI11: Sí | CJ11: Sí, parientes lejanos | CK11: Sí | CL11: Sí | CM11: 07:36 | CN11: Mate | CO11: 12:30 | CP11: 107 | CQ11: 294 | CR11: Sí | CS11: 15 | CT11: Alto | CU11: 33 % | CV11: Sí | CW11: 6 | CX11: 2 | CY11: Bajo
A12: demo-11 | B12: A1-0011 | C12: 011-68-4612 | D12: 11 | E12: 68 | F12: 4612 | G12: 46301 | H12: 12:02 | J12: A | K12: 1 | L12: Encuestador A | M12: Puesto 1 | N12: Sí | O12: Sí | P12: 38 | Q12: Sí | R12: Sí | S12: Sí | T12: finalizado | U12: 2026-10-v2 | V12: 2026-10-06T15:00:00.000Z | W12: Argentina | Y12: Secundaria incompleta | Z12: No | AA12: 1 | AB12: 4 | AC12: Español | AE12: Español | AG12: Argentina | AI12: Muy malo | AJ12: 3 | AK12: Viaje interprovincial | AL12: Una vez al mes | AN12: 3 veces por semana | AP12: Empleado | AR12: Parcialmente conforme | AS12: Duda | AT12: 2.4 | AU12: Sí | AV12: En el camión al costado de la ruta | AX12: 8 | AY12: Nunca | AZ12: Gaseosas; Agua; Café | BB12: Nunca | BC12: No | BD12: No | BE12: No | BF12: Ninguna | BG12: Sistema privado | BH12: Una vez al año | BI12: Sistema público; Otros (medicina tradicional, alternativa, etc.) | BJ12: Sí | BK12: Rodillas | BL12: Ninguno | BN12: Obesidad | BP12: Una vez a la semana | BQ12: Yerba mate | BS12: Sí | BT12: No | BU12: Siempre | BV12: Sí | BW12: No | BX12: Varón | BY12: 94.9 | BZ12: 1.75 | CA12: 31 | CB12: 111 | CC12: 117 | CD12: 75 | CE12: No | CF12: Sí | CG12: Sí | CH12: No | CI12: No | CJ12: No | CK12: Sí | CL12: Sí | CM12: 07:17 | CN12: Mate | CO12: 13:30 | CP12: 113 | CQ12: 373 | CR12: Sí | CS12: 13 | CT12: Moderado | CU12: 17 % | CV12: Sí | CW12: 14 | CX12: 16 | CY12: Moderado
A13: demo-12 | B13: B1-0012 | C13: 211-26-4630 | D13: 211 | E13: 26 | F13: 4630 | G13: 46294 | H13: 12:05 | J13: B | K13: 1 | L13: Encuestador B | M13: Puesto 2 | N13: Sí | O13: Sí | P13: 38 | Q13: Sí | R13: Sí | S13: Sí | T13: finalizado | U13: 2026-10-v2 | V13: 2026-09-29T15:00:00.000Z | W13: Brasil | Y13: Terciario completo | Z13: No | AA13: 3 | AB13: Más de 5 | AC13: Guaraní | AE13: Español | AG13: Argentina | AI13: Regular | AJ13: 6 | AK13: Viaje internacional | AL13: Una vez a la semana | AN13: 3 veces por semana | AP13: Empleado | AR13: Parcialmente conforme | AS13: No | AT13: 8.3 | AU13: No | AV13: Estaciones de servicio | AX13: 7.9 | AY13: Todos los días | AZ13: Mate; Jugos artificiales; Gaseosas | BB13: A veces | BC13: Rara vez | BD13: Sí | BE13: Parcialmente | BF13: Obra social | BG13: Sistema público | BH13: Solo cuando me siento mal | BI13: Sistema público; Otros (medicina tradicional, alternativa, etc.) | BJ13: Sí | BK13: Lumbar | BL13: Ninguno | BN13: Obesidad | BP13: Rara vez | BQ13: No | BS13: No | BT13: No | BU13: Siempre | BV13: No | BW13: No | BX13: Varón | BY13: 95.7 | BZ13: 1.82 | CA13: 28.9 | CB13: 84 | CC13: 147 | CD13: 93 | CE13: Sí | CF13: Sí | CG13: No | CH13: No | CI13: No | CJ13: No | CK13: No | CL13: Sí | CM13: 07:13 | CN13: Mate | CO13: 11:30 | CP13: 178 | CQ13: 257 | CR13: Sí | CS13: 1 | CT13: Bajo | CU13: 1 % | CV13: Sí | CW13: -7 | CX13: <1 | CY13: Bajo
A14: demo-13 | B14: C1-0013 | C14: 412-38-4612 | D14: 412 | E14: 38 | F14: 4612 | G14: 46296 | H14: 13:04 | J14: C | K14: 1 | L14: Encuestador C | M14: Puesto 2 | N14: Sí | O14: Sí | P14: 39 | Q14: Sí | R14: Sí | S14: Sí | T14: borrador | U14: 2026-10-v2 | V14: 2026-10-01T15:00:00.000Z | W14: Paraguay | Y14: Secundaria completa | Z14: No | AA14: 1 | AB14: 1 | AC14: Guaraní; Español | AE14: Español | AG14: Argentina | AI14: Bueno | AJ14: 16 | AK14: Viaje interprovincial | AL14: Una vez al mes | AN14: Diariamente | AP14: Empleado | AR14: Conforme | AS14: Duda | AT14: 4.2 | AU14: Sí | AV14: En el camión al costado de la ruta | AX14: 6.3 | AY14: Nunca | AZ14: Gaseosas | BB14: Sí, siempre | BC14: Sí | BD14: No | BE14: Parcialmente | BF14: Obra social | BG14: Ninguno | BH14: Nunca | BI14: Sistema privado | BJ14: Sí | BK14: Rodillas | BL14: Medicamentos; Hierbas | BM14: Ibuprofeno | BN14: Obesidad | BP14: Nunca | BQ14: Café | BS14: No | BT14: No | BU14: Siempre | BV14: No | BW14: No | BX14: Varón | BY14: 65.1 | BZ14: 1.65 | CA14: 23.9 | CB14: 113 | CC14: 149 | CD14: 94 | CE14: No | CF14: No | CG14: Sí | CH14: No | CI14: No | CJ14: Sí, primer grado | CK14: No | CL14: Sí | CM14: 07:49 | CN14: Mate | CO14: 14:30 | CP14: 79 | CQ14: 401 | CR14: Sí | CS14: 12 | CT14: Moderado | CU14: 17 % | CV14: Sí | CW14: -3 | CX14: <1 | CY14: Bajo
A15: demo-14 | B15: A1-0014 | C15: 014-43-4400 | D15: 14 | E15: 43 | F15: 4400 | G15: 46301 | H15: 13:03 | J15: A | K15: 1 | L15: Encuestador A | M15: Puesto 1 | N15: Sí | O15: Sí | P15: 39 | Q15: Sí | R15: Sí | S15: Sí | T15: finalizado | U15: 2026-10-v2 | V15: 2026-10-06T15:00:00.000Z | W15: Brasil | Y15: Secundaria incompleta | Z15: Sí | AA15: 3 | AB15: 1 | AC15: Guaraní; Español | AE15: Español | AG15: Argentina | AI15: Muy malo | AJ15: 22 | AK15: Viaje provincial (Jujuy) | AL15: Quincenalmente | AN15: Una vez a la semana | AP15: Empleado | AR15: Disconforme | AS15: No | AT15: 4.6 | AU15: Sí | AV15: Estaciones de servicio | AX15: 5.5 | AY15: Nunca | AZ15: Gaseosas | BB15: A veces | BC15: Sí | BD15: No | BE15: Sí | BF15: Obra social | BG15: Ninguno | BH15: 2 veces al año | BI15: Sistema privado | BJ15: Sí | BK15: Rodillas | BL15: Medicamentos | BM15: Ibuprofeno | BN15: Musculoesqueléticos; Digestivas | BP15: Rara vez | BQ15: Energizantes (Speed, Monster, Red Bull, etc.) | BS15: No | BT15: Sí | BU15: Nunca | BV15: Sí | BW15: No | BX15: Varón | BY15: 75.7 | BZ15: 1.63 | CA15: 28.5 | CB15: 115 | CC15: 125 | CD15: 80 | CE15: Sí | CF15: No | CG15: No | CH15: No | CI15: No | CJ15: Sí, primer grado | CK15: No | CL15: Sí | CM15: 07:13 | CN15: Mate | CO15: 10:30 | CP15: 181 | CQ15: 197 | CR15: Sí | CS15: 11 | CT15: Ligeramente elevado | CU15: 4 % | CV15: Sí | CW15: 1 | CX15: 1 | CY15: Bajo
A16: demo-15 | B16: B1-0015 | C16: 214-59-4500 | D16: 214 | E16: 59 | F16: 4500 | G16: 46294 | H16: 11:03 | J16: B | K16: 1 | L16: Encuestador B | M16: Puesto 2 | N16: Sí | O16: Sí | P16: 39 | Q16: Sí | R16: Sí | S16: Sí | T16: finalizado | U16: 2026-10-v2 | V16: 2026-09-29T15:00:00.000Z | W16: Argentina | Y16: Secundaria incompleta | Z16: Sí | AA16: 3 | AB16: 1 | AC16: Guaraní | AE16: Español | AG16: Argentina | AI16: Regular | AJ16: 37 | AK16: Viaje provincial (Jujuy) | AL16: 2 veces por semana | AN16: 2 veces por semana | AP16: Dueño del camión | AR16: Parcialmente conforme | AS16: Duda | AT16: 2.1 | AU16: Sí | AV16: Paradores; En el camión al costado de la ruta | AX16: 6.9 | AY16: Varias veces por semana | AZ16: Jugos artificiales; Café | BB16: Nunca | BC16: Rara vez | BD16: Sí | BE16: No | BF16: Obra social | BG16: Sistema público | BH16: Solo cuando me siento mal | BI16: Sistema público; Otros (medicina tradicional, alternativa, etc.) | BJ16: Sí | BK16: Cervical | BL16: Medicamentos; Hierbas | BM16: Ibuprofeno | BN16: No tengo diagnóstico de enfermedad | BP16: Rara vez | BQ16: Energizantes (Speed, Monster, Red Bull, etc.) | BS16: Sí | BT16: Sí | BU16: A veces | BV16: No | BW16: Sí | BX16: Varón | BY16: 116.3 | BZ16: 1.8 | CA16: 35.9 | CB16: 78 | CC16: 146 | CD16: 93 | CE16: No | CF16: Sí | CG16: No | CH16: No | CI16: No | CJ16: No | CK16: No | CL16: Sí | CM16: 07:45 | CN16: Mate | CO16: 14:30 | CP16: 110 | CQ16: 405 | CR16: No | CV16: Sí | CW16: 14 | CX16: 16 | CY16: Moderado
A17: demo-16 | B17: C1-0016 | C17: 415-38-4500 | D17: 415 | E17: 38 | F17: 4500 | G17: 46295 | H17: 16:02 | J17: C | K17: 1 | L17: Encuestador C | M17: Puesto 1 | N17: Sí | O17: Sí | P17: 39 | Q17: Sí | R17: Sí | S17: Sí | T17: finalizado | U17: 2026-10-v2 | V17: 2026-09-30T15:00:00.000Z | W17: Brasil | Y17: Secundaria incompleta | Z17: Sí | AA17: Más de 5 | AB17: 3 | AC17: Portugués | AE17: Español | AG17: Argentina | AI17: Regular | AJ17: 6 | AK17: Viaje internacional | AL17: Quincenalmente | AN17: 2 veces por semana | AP17: Empleado | AR17: Parcialmente conforme | AS17: Duda | AT17: 7.8 | AU17: Sí | AV17: En el camión al costado de la ruta | AX17: 5.9 | AY17: Todos los días | AZ17: Gaseosas | BB17: Sí, siempre | BC17: Rara vez | BD17: No | BE17: No | BF17: Obra social | BG17: Sistema privado | BH17: Nunca | BI17: Sistema público; Otros (medicina tradicional, alternativa, etc.) | BJ17: Sí | BK17: Cervical | BL17: Medicamentos | BM17: Ibuprofeno | BN17: Obesidad | BP17: 2 a 3 veces por semana | BQ17: Energizantes (Speed, Monster, Red Bull, etc.) | BS17: Sí | BT17: Sí | BU17: Nunca | BV17: No | BW17: No | BX17: Varón | BY17: 57.1 | BZ17: 1.63 | CA17: 21.5 | CB17: 88 | CC17: 135 | CD17: 86 | CE17: Sí | CF17: No | CG17: Sí | CH17: No | CI17: No | CJ17: No | CK17: Sí | CL17: Sí | CM17: 07:28 | CN17: Mate | CO17: 11:30 | CP17: 146 | CQ17: 242 | CR17: Sí | CS17: 1 | CT17: Bajo | CU17: 1 % | CV17: Sí | CW17: 5 | CX17: 2 | CY17: Bajo
A18: demo-17 | B18: B1-0017 | C18: 216-28-4500 | D18: 216 | E18: 28 | F18: 4500 | G18: 46289 | H18: 16:08 | J18: B | K18: 1 | L18: Encuestador B | M18: Puesto 2 | N18: Sí | O18: Sí | P18: 38 | Q18: Sí | R18: Sí | S18: Sí | T18: finalizado | U18: 2026-10-v2 | V18: 2026-09-24T15:00:00.000Z | W18: Argentina | Y18: Terciario incompleto | Z18: Sí | AA18: Más de 5 | AB18: Más de 5 | AC18: Guaraní; Español | AE18: Español | AG18: Argentina | AI18: Muy malo | AJ18: 7 | AK18: Viaje internacional | AL18: Una vez a la semana | AN18: Una vez a la semana | AP18: Dueño del camión | AR18: Disconforme | AS18: Sí | AT18: 4 | AU18: Sí | AV18: En el camión al costado de la ruta; Paradores | AX18: 5.6 | AY18: Varias veces por semana | AZ18: Agua; Jugos artificiales | BB18: Sí, siempre | BC18: Algunas veces | BD18: No | BE18: Sí | BF18: Obra social | BG18: Sistema privado | BH18: Una vez al año | BI18: Sistema público; Otros (medicina tradicional, alternativa, etc.) | BJ18: Sí | BK18: Rodillas | BL18: Ninguno | BN18: Musculoesqueléticos | BP18: 2 a 3 veces por semana | BQ18: Yerba mate | BS18: Sí | BT18: Sí | BU18: Nunca | BV18: Sí | BW18: No | BX18: Varón | BY18: 94.2 | BZ18: 1.76 | CA18: 30.4 | CB18: 113 | CC18: 116 | CD18: 74 | CE18: Sí | CF18: Sí | CG18: No | CH18: No | CI18: No | CJ18: No | CK18: No | CL18: Sí | CM18: 07:44 | CN18: Mate | CO18: 11:30 | CP18: 136 | CQ18: 226 | CR18: Sí | CS18: 7 | CT18: Ligeramente elevado | CU18: 4 % | CV18: Sí | CW18: -6 | CX18: <1 | CY18: Bajo
A19: demo-18 | B19: B1-0018 | C19: 217-50-4600 | D19: 217 | E19: 50 | F19: 4600 | G19: 46290 | H19: 13:05 | J19: B | K19: 1 | L19: Encuestador B | M19: Puesto 2 | N19: Sí | O19: Sí | P19: 39 | Q19: Sí | R19: Sí | S19: Sí | T19: finalizado | U19: 2026-10-v2 | V19: 2026-09-25T15:00:00.000Z | W19: Chile | Y19: Primaria completa | Z19: Sí | AA19: 5 | AB19: 3 | AC19: Guaraní; Inglés | AE19: Español | AG19: Argentina | AI19: Regular | AJ19: 2 | AK19: Viaje internacional | AL19: Quincenalmente | AN19: Una vez a la semana | AP19: Dueño del camión | AR19: Conforme | AS19: Sí | AT19: 3.8 | AU19: Sí | AV19: Paradores | AX19: 5.4 | AY19: Todos los días | AZ19: Gaseosas; Agua | BB19: Nunca | BC19: Rara vez | BD19: No | BE19: No | BF19: Obra social | BG19: Sistema público | BH19: Solo cuando me siento mal | BI19: Sistema privado | BJ19: No | BL19: Medicamentos; Hierbas | BM19: Ibuprofeno | BN19: No tengo diagnóstico de enfermedad | BP19: Rara vez | BQ19: Energizantes (Speed, Monster, Red Bull, etc.) | BS19: Sí | BT19: Sí | BU19: A veces | BV19: Sí | BW19: Sí | BX19: Varón | BY19: 79.7 | BZ19: 1.87 | CA19: 22.8 | CB19: 88 | CC19: 110 | CD19: 70 | CE19: Sí | CF19: No | CG19: No | CH19: No | CI19: No | CJ19: No | CK19: Sí | CL19: Sí | CM19: 07:24 | CN19: Mate | CO19: 11:30 | CP19: 99 | CQ19: 246 | CR19: No | CV19: Sí | CW19: 12 | CX19: 10 | CY19: Moderado
A20: demo-19 | B20: C1-0019 | C20: 418-42-4630 | D20: 418 | E20: 42 | F20: 4630 | G20: 46290 | H20: 17:06 | J20: C | K20: 1 | L20: Encuestador C | M20: Puesto 1 | N20: Sí | O20: Sí | P20: 39 | Q20: Sí | R20: Sí | S20: Sí | T20: finalizado | U20: 2026-10-v2 | V20: 2026-09-25T15:00:00.000Z | W20: Argentina | Y20: Secundaria incompleta | Z20: Sí | AA20: 3 | AB20: Más de 5 | AC20: Guaraní; Portugués | AE20: Español | AG20: Argentina | AI20: Bueno | AJ20: 8 | AK20: Viaje interprovincial | AL20: Una vez a la semana | AN20: Una vez a la semana | AP20: Empleado | AR20: Disconforme | AS20: Sí | AT20: 7.3 | AU20: Sí | AV20: Paradores | AX20: 5.7 | AY20: Todos los días | AZ20: Jugos artificiales; Gaseosas | BB20: Nunca | BC20: Rara vez | BD20: No | BE20: Sí | BF20: Obra social | BG20: Sistema público | BH20: Nunca | BI20: Sistema público; Otros (medicina tradicional, alternativa, etc.) | BJ20: No | BL20: Medicamentos | BM20: Ibuprofeno | BN20: Obesidad | BP20: Nunca | BQ20: Café | BS20: Sí | BT20: No | BU20: Siempre | BV20: No | BW20: No | BX20: Mujer | BY20: 86 | BZ20: 1.59 | CA20: 34 | CB20: 96 | CC20: 124 | CD20: 79 | CE20: Sí | CF20: Sí | CG20: No | CH20: No | CI20: Sí | CJ20: Sí, parientes lejanos | CK20: Sí | CL20: Sí | CM20: 07:44 | CN20: Mate | CO20: 12:30 | CP20: 186 | CQ20: 286 | CR20: Sí | CS20: 15 | CT20: Alto | CU20: 33 % | CV20: Sí | CW20: 13 | CX20: 2 | CY20: Bajo
A21: demo-20 | B21: C1-0020 | C21: 419-62-4500 | D21: 419 | E21: 62 | F21: 4500 | G21: 46296 | H21: 16:08 | J21: C | K21: 1 | L21: Encuestador C | M21: Puesto 2 | N21: Sí | O21: Sí | P21: 38 | Q21: Sí | R21: Sí | S21: Sí | T21: finalizado | U21: 2026-10-v2 | V21: 2026-10-01T15:00:00.000Z | W21: Argentina | Y21: Secundaria completa | Z21: No | AA21: 5 | AB21: 5 | AC21: Portugués | AE21: Español | AG21: Argentina | AI21: Muy malo | AJ21: 27 | AK21: Viaje provincial (Jujuy) | AL21: Una vez a la semana | AN21: 3 veces por semana | AP21: Empleado | AR21: Conforme | AS21: Duda | AT21: 3.9 | AU21: Sí | AV21: Paradores | AX21: 6 | AY21: Todos los días | AZ21: Mate; Agua | BB21: A veces | BC21: Sí | BD21: Sí | BE21: Sí | BF21: Obra social; Prepaga | BG21: Ninguno | BH21: 2 veces al año | BI21: Sistema público | BJ21: No | BL21: Ninguno | BN21: Musculoesqueléticos; Digestivas | BP21: Nunca | BQ21: Café; Coca-Cola | BS21: Sí | BT21: Sí | BU21: Nunca | BV21: No | BW21: No | BX21: Varón | BY21: 57.7 | BZ21: 1.65 | CA21: 21.2 | CB21: 105 | CC21: 121 | CD21: 77 | CE21: No | CF21: Sí | CG21: No | CH21: No | CI21: No | CJ21: No | CK21: No | CL21: Sí | CM21: 07:44 | CN21: Mate | CO21: 11:30 | CP21: 85 | CQ21: 226 | CR21: Sí | CS21: 9 | CT21: Ligeramente elevado | CU21: 4 % | CV21: Sí | CW21: 10 | CX21: 6 | CY21: Bajo
A22: demo-21 | B22: A1-0021 | C22: 021-58-4630 | D22: 21 | E22: 58 | F22: 4630 | G22: 46294 | H22: 16:04 | J22: A | K22: 1 | L22: Encuestador A | M22: Puesto 2 | N22: Sí | O22: Sí | P22: 38 | Q22: Sí | R22: No | S22: No | T22: finalizado | U22: 2026-10-v2 | V22: 2026-09-29T15:00:00.000Z | W22: Argentina | Y22: Secundaria completa | Z22: Sí | AA22: 4 | AB22: 1 | AC22: Portugués | AE22: Español | AG22: Argentina | AI22: Muy bueno | AJ22: 38 | AK22: Viaje interprovincial | AL22: 2 veces por semana | AN22: Una vez a la semana | AP22: Empleado | AR22: Conforme | AS22: Duda | AT22: 5.3 | AU22: Sí | AV22: En el camión al costado de la ruta | AX22: 6.3 | AY22: Varias veces por semana | AZ22: Mate; Café | BB22: Casi nunca | BC22: No | BD22: No | BE22: Sí | BF22: Ninguna | BG22: Ninguno | BH22: 2 veces al año | BI22: Sistema público | BJ22: Sí | BK22: Rodillas | BL22: Ninguno | BN22: Musculoesqueléticos; Digestivas | BP22: Rara vez | BQ22: No | BS22: No | BT22: Sí | BU22: A veces | BV22: No
A23: demo-22 | B23: C1-0022 | C23: 421-56-4600 | D23: 421 | E23: 56 | F23: 4600 | G23: 46302 | H23: 10:02 | J23: C | K23: 1 | L23: Encuestador C | M23: Puesto 2 | N23: Sí | O23: Sí | P23: 39 | Q23: Sí | R23: Sí | S23: Sí | T23: borrador | U23: 2026-10-v2 | V23: 2026-10-07T15:00:00.000Z | W23: Chile | Y23: Terciario incompleto | Z23: Sí | AA23: Más de 5 | AB23: Más de 5 | AC23: Guaraní | AE23: Español | AG23: Argentina | AI23: Bueno | AJ23: 18 | AK23: Viaje internacional | AL23: Una vez al mes | AN23: Una vez a la semana | AP23: Empleado | AR23: Parcialmente conforme | AS23: No | AT23: 7 | AU23: Sí | AV23: En el camión al costado de la ruta | AX23: 5.2 | AY23: Varias veces por semana | AZ23: Mate; Agua | BB23: A veces | BC23: Sí | BD23: No | BE23: Sí | BF23: Ninguna | BG23: Ninguno | BH23: Solo cuando me siento mal | BI23: Sistema público; Otros (medicina tradicional, alternativa, etc.) | BJ23: Sí | BK23: Lumbar | BL23: Medicamentos | BM23: Ibuprofeno | BN23: No tengo diagnóstico de enfermedad | BP23: Rara vez | BQ23: Café | BS23: Sí | BT23: Sí | BU23: A veces | BV23: Sí | BW23: No | BX23: Varón | BY23: 75.5 | BZ23: 1.8 | CA23: 23.3 | CB23: 103 | CC23: 147 | CD23: 93 | CE23: No | CF23: No | CG23: No | CH23: No | CI23: No | CJ23: No | CK23: No | CL23: Sí | CM23: 07:10 | CN23: Mate | CO23: 14:30 | CP23: 174 | CQ23: 440 | CR23: Sí | CS23: 10 | CT23: Ligeramente elevado | CU23: 4 % | CV23: Sí | CW23: 9 | CX23: 5 | CY23: Bajo
A24: demo-23 | B24: C1-0023 | C24: 422-25-4500 | D24: 422 | E24: 25 | F24: 4500 | G24: 46296 | H24: 15:08 | J24: C | K24: 1 | L24: Encuestador C | M24: Puesto 1 | N24: Sí | O24: Sí | P24: 39 | Q24: Sí | R24: Sí | S24: Sí | T24: finalizado | U24: 2026-10-v2 | V24: 2026-10-01T15:00:00.000Z | W24: Paraguay | Y24: Universitario incompleto | Z24: No | AA24: 5 | AB24: 4 | AC24: Inglés; Guaraní | AE24: Español | AG24: Argentina | AI24: Muy malo | AJ24: 4 | AK24: Viaje interprovincial | AL24: Una vez a la semana | AN24: Diariamente | AP24: Empleado | AR24: Parcialmente conforme | AS24: No | AT24: 2.2 | AU24: Sí | AV24: En el camión al costado de la ruta | AX24: 7.9 | AY24: Todos los días | AZ24: Agua | BB24: A veces | BC24: No | BD24: No | BE24: No | BF24: Ninguna | BG24: Ninguno | BH24: 2 veces al año | BI24: Sistema privado | BJ24: No | BL24: Medicamentos | BM24: Ibuprofeno | BN24: Musculoesqueléticos; Digestivas | BP24: Nunca | BQ24: Café | BS24: Sí | BT24: Sí | BU24: Siempre | BV24: Sí | BW24: No | BX24: Varón | BY24: 90.4 | BZ24: 1.67 | CA24: 32.4 | CB24: 97 | CC24: 141 | CD24: 89 | CE24: No | CF24: Sí | CG24: No | CH24: No | CI24: No | CJ24: Sí, parientes lejanos | CK24: No | CL24: Sí | CM24: 07:44 | CN24: Mate | CO24: 11:30 | CP24: 81 | CQ24: 226 | CR24: Sí | CS24: 11 | CT24: Ligeramente elevado | CU24: 4 % | CV24: Sí | CW24: -5 | CX24: <1 | CY24: Bajo
A25: demo-24 | B25: A1-0024 | C25: 024-49-4400 | D25: 24 | E25: 49 | F25: 4400 | G25: 46289 | H25: 16:03 | J25: A | K25: 1 | L25: Encuestador A | M25: Puesto 2 | N25: Sí | O25: Sí | P25: 38 | Q25: Sí | R25: Sí | S25: Sí | T25: finalizado | U25: 2026-10-v2 | V25: 2026-09-24T15:00:00.000Z | W25: Brasil | Y25: Primaria completa | Z25: Sí | AA25: 1 | AB25: 5 | AC25: Guaraní; Español | AE25: Español | AG25: Argentina | AI25: Regular | AJ25: 25 | AK25: Viaje internacional | AL25: Una vez a la semana | AN25: Diariamente | AP25: Empleado | AR25: Conforme | AS25: Sí | AT25: 2.9 | AU25: Sí | AV25: En el camión al costado de la ruta | AX25: 4.8 | AY25: Nunca | AZ25: Café; Jugos artificiales; Mate | BB25: Sí, siempre | BC25: No | BD25: No | BE25: Sí | BF25: Ninguna | BG25: Ninguno | BH25: Una vez al año | BI25: Sistema público | BJ25: Sí | BK25: Rodillas | BL25: Ninguno | BN25: No tengo diagnóstico de enfermedad | BP25: 2 a 3 veces por semana | BQ25: Café; Coca-Cola | BS25: Sí | BT25: Sí | BU25: A veces | BV25: No | BW25: No | BX25: Varón | BY25: 90.1 | BZ25: 1.84 | CA25: 26.6 | CB25: 116 | CC25: 161 | CD25: 102 | CE25: Sí | CF25: Sí | CG25: Sí | CH25: No | CI25: No | CJ25: No | CK25: Sí | CL25: Sí | CM25: 07:10 | CN25: Mate | CO25: 12:30 | CP25: 117 | CQ25: 320 | CR25: Sí | CS25: 7 | CT25: Ligeramente elevado | CU25: 4 % | CV25: Sí | CW25: 11 | CX25: 8 | CY25: Bajo
A26: demo-25 | B26: A1-0025 | C26: 025-44-4630 | D26: 25 | E26: 44 | F26: 4630 | G26: 46289 | H26: 12:00 | J26: A | K26: 1 | L26: Encuestador A | M26: Puesto 2 | N26: Sí | O26: No | P26: 39 | Q26: Sí | R26: Sí | S26: Sí | T26: finalizado | U26: 2026-10-v2 | V26: 2026-09-24T15:00:00.000Z | W26: Argentina | Y26: Terciario incompleto | Z26: Sí | AA26: 5 | AB26: 5 | AC26: Español | AE26: Español | AG26: Argentina | AI26: Regular | AJ26: 6 | AK26: Viaje provincial (Jujuy) | AL26: Quincenalmente | AN26: Diariamente | AP26: Empleado | AR26: Conforme | AS26: Duda | AT26: 2.7 | AU26: Sí | AV26: Estaciones de servicio | AX26: 4.6 | AY26: Nunca | AZ26: Gaseosas; Agua | BB26: Sí, siempre | BC26: No | BD26: No | BE26: Sí | BF26: Obra social | BG26: Ninguno | BH26: Solo cuando me siento mal | BI26: Sistema privado | BJ26: Sí | BK26: Cervical | BL26: Medicamentos | BM26: Ibuprofeno | BN26: Musculoesqueléticos | BP26: Una vez a la semana | BQ26: Café | BS26: No | BT26: No | BU26: Nunca | BV26: Sí | BW26: No | BX26: Mujer | BY26: 63.4 | BZ26: 1.65 | CA26: 23.3 | CB26: 99 | CC26: 116 | CD26: 74 | CE26: No | CF26: No | CG26: No | CH26: No | CI26: No | CJ26: Sí, primer grado | CK26: Sí | CL26: Sí | CM26: 07:29 | CN26: Mate | CO26: 14:30 | CP26: 138 | CQ26: 421 | CR26: Sí | CS26: 12 | CT26: Moderado | CU26: 17 % | CV26: Sí | CW26: 8 | CX26: <1 | CY26: Bajo
A27: demo-26 | B27: B1-0026 | C27: 225-66-4400 | D27: 225 | E27: 66 | F27: 4400 | G27: 46294 | H27: 12:06 | J27: B | K27: 1 | L27: Encuestador B | M27: Puesto 2 | N27: Sí | O27: No | P27: 38 | Q27: Sí | R27: Sí | S27: No | T27: finalizado | U27: 2026-10-v2 | V27: 2026-09-29T15:00:00.000Z | W27: Argentina | Y27: Secundaria completa | Z27: No | AA27: 5 | AB27: 3 | AC27: Portugués | AE27: Español | AG27: Argentina | AI27: Regular | AJ27: 14 | AK27: Viaje internacional | AL27: 2 veces por semana | AN27: 3 veces por semana | AP27: Empleado | AR27: Parcialmente conforme | AS27: No | AT27: 2.5 | AU27: Sí | AV27: Estaciones de servicio | AX27: 7.2 | AY27: Todos los días | AZ27: Agua | BB27: Casi nunca | BC27: No | BD27: No | BE27: No | BF27: Obra social | BG27: Sistema privado | BH27: 2 veces al año | BI27: Sistema público; Otros (medicina tradicional, alternativa, etc.) | BJ27: Sí | BK27: Rodillas | BL27: Ninguno | BN27: Musculoesqueléticos; Digestivas | BP27: Una vez a la semana | BQ27: Energizantes (Speed, Monster, Red Bull, etc.) | BS27: Sí | BT27: No | BU27: Siempre | BV27: Sí | BW27: No | BX27: Varón | BY27: 69.6 | BZ27: 1.82 | CA27: 21 | CB27: 110 | CC27: 113 | CD27: 72 | CE27: Sí | CF27: No | CG27: Sí | CH27: No | CI27: No | CJ27: Sí, parientes lejanos | CK27: No | CL27: No | CR27: Sí | CS27: 12 | CT27: Moderado | CU27: 17 % | CV27: Sí | CW27: 11 | CX27: 8 | CY27: Bajo
A28: demo-27 | B28: B1-0027 | C28: 226-39-4612 | D28: 226 | E28: 39 | F28: 4612 | G28: 46295 | H28: 16:05 | J28: B | K28: 1 | L28: Encuestador B | M28: Puesto 2 | N28: Sí | O28: No | P28: 39 | Q28: Sí | R28: Sí | S28: Sí | T28: finalizado | U28: 2026-10-v2 | V28: 2026-09-30T15:00:00.000Z | W28: Argentina | Y28: Primaria completa | Z28: No | AA28: Más de 5 | AB28: 1 | AC28: Guaraní | AE28: Español | AG28: Argentina | AI28: Bueno | AJ28: 19 | AK28: Viaje interprovincial | AL28: 2 veces por semana | AN28: Diariamente | AP28: Dueño del camión | AR28: Conforme | AS28: Sí | AT28: 5.1 | AU28: Sí | AV28: En el camión al costado de la ruta | AX28: 4.7 | AY28: Nunca | AZ28: Gaseosas | BB28: A veces | BC28: Sí | BD28: Sí | BE28: Parcialmente | BF28: Ninguna | BG28: Sistema público | BH28: 2 veces al año | BI28: Sistema público | BJ28: No | BL28: Medicamentos; Hierbas | BM28: Ibuprofeno | BN28: Musculoesqueléticos; Digestivas | BP28: 2 a 3 veces por semana | BQ28: No | BS28: Sí | BT28: No | BU28: Nunca | BV28: No | BW28: Sí | BX28: Varón | BY28: 69.9 | BZ28: 1.7 | CA28: 24.2 | CB28: 92 | CC28: 155 | CD28: 98 | CE28: No | CF28: No | CG28: Sí | CH28: No | CI28: No | CJ28: No | CK28: No | CL28: Sí | CM28: 07:44 | CN28: Mate | CO28: 13:30 | CP28: 173 | CQ28: 346 | CR28: No | CV28: Sí | CW28: 0 | CX28: 1 | CY28: Bajo
A29: demo-28 | B29: B1-0028 | C29: 227-66-4600 | D29: 227 | E29: 66 | F29: 4600 | G29: 46302 | H29: 14:01 | J29: B | K29: 1 | L29: Encuestador B | M29: Puesto 2 | N29: Sí | O29: No | P29: 38 | Q29: Sí | R29: Sí | S29: Sí | T29: finalizado | U29: 2026-10-v2 | V29: 2026-10-07T15:00:00.000Z | W29: Paraguay | Y29: Secundaria completa | Z29: No | AA29: Más de 5 | AB29: 2 | AC29: Español | AE29: Español | AG29: Argentina | AI29: Regular | AJ29: 22 | AK29: Viaje internacional | AL29: Quincenalmente | AN29: 3 veces por semana | AP29: Empleado | AR29: Conforme | AS29: No | AT29: 4.8 | AU29: Sí | AV29: Estaciones de servicio | AX29: 6.1 | AY29: Todos los días | AZ29: Gaseosas; Jugos artificiales | BB29: Casi nunca | BC29: No | BD29: No | BE29: No | BF29: Obra social | BG29: Sistema privado | BH29: Una vez al año | BI29: Sistema público; Otros (medicina tradicional, alternativa, etc.) | BJ29: Sí | BK29: Cervical | BL29: Ninguno | BN29: No tengo diagnóstico de enfermedad | BP29: Nunca | BQ29: Café | BS29: Sí | BT29: No | BU29: A veces | BV29: Sí | BW29: Sí | BX29: Varón | BY29: 79.6 | BZ29: 1.86 | CA29: 23 | CB29: 111 | CC29: 134 | CD29: 85 | CE29: Sí | CF29: No | CG29: No | CH29: No | CI29: No | CJ29: Sí, parientes lejanos | CK29: Sí | CL29: Sí | CM29: 07:43 | CN29: Mate | CO29: 12:30 | CP29: 176 | CQ29: 287 | CR29: No | CV29: Sí | CW29: 16 | CX29: 25 | CY29: Alto
A30: demo-29 | B30: A1-0029 | C30: 029-42-4612 | D30: 29 | E30: 42 | F30: 4612 | G30: 46289 | H30: 11:08 | J30: A | K30: 1 | L30: Encuestador A | M30: Puesto 1 | N30: Sí | O30: Sí | P30: 38 | Q30: Sí | R30: Sí | S30: Sí | T30: finalizado | U30: 2026-10-v2 | V30: 2026-09-24T15:00:00.000Z | W30: Argentina | Y30: Secundaria completa | Z30: Sí | AA30: 2 | AB30: 5 | AC30: Inglés; Guaraní | AE30: Español | AG30: Argentina | AI30: Regular | AJ30: 7 | AK30: Viaje provincial (Jujuy) | AL30: Una vez al mes | AN30: 3 veces por semana | AP30: Empleado | AR30: Conforme | AS30: Sí | AT30: 8.6 | AU30: Sí | AV30: Estaciones de servicio | AX30: 4 | AY30: Casi nunca | AZ30: Agua; Mate | BB30: Sí, siempre | BC30: Algunas veces | BD30: No | BE30: Parcialmente | BF30: Obra social | BG30: Sistema público | BH30: 2 veces al año | BI30: Sistema público | BJ30: No | BL30: Ninguno | BN30: No tengo diagnóstico de enfermedad | BP30: 2 a 3 veces por semana | BQ30: Café; Coca-Cola | BS30: Sí | BT30: Sí | BU30: Nunca | BV30: Sí | BW30: No | BX30: Varón | BY30: 125.8 | BZ30: 1.88 | CA30: 35.6 | CB30: 79 | CC30: 121 | CD30: 77 | CE30: No | CF30: No | CG30: No | CH30: No | CI30: No | CJ30: No | CK30: Sí | CL30: Sí | CM30: 07:21 | CN30: Mate | CO30: 15:30 | CP30: 93 | CQ30: 489 | CR30: Sí | CS30: 6 | CT30: Bajo | CU30: 1 % | CV30: Sí | CW30: 7 | CX30: 3 | CY30: Bajo
A31: demo-30 | B31: C1-0030 | C31: 429-32-4612 | D31: 429 | E31: 32 | F31: 4612 | G31: 46290 | H31: 16:01 | J31: C | K31: 1 | L31: Encuestador C | M31: Puesto 1 | N31: Sí | O31: No | P31: 39 | Q31: Sí | R31: Sí | S31: Sí | T31: finalizado | U31: 2026-10-v2 | V31: 2026-09-25T15:00:00.000Z | W31: Argentina | Y31: Secundaria incompleta | Z31: Sí | AA31: 1 | AB31: 1 | AC31: Portugués | AE31: Español | AG31: Argentina | AI31: Malo | AJ31: 6 | AK31: Viaje interprovincial | AL31: Quincenalmente | AN31: Diariamente | AP31: Empleado | AR31: Parcialmente conforme | AS31: Duda | AT31: 2.2 | AU31: Sí | AV31: Estaciones de servicio | AX31: 5.6 | AY31: Casi nunca | AZ31: Gaseosas | BB31: Nunca | BC31: No | BD31: No | BE31: Parcialmente | BF31: Obra social | BG31: Sistema público | BH31: 2 veces al año | BI31: Sistema público | BJ31: No | BL31: Medicamentos; Hierbas | BM31: Ibuprofeno | BN31: Musculoesqueléticos; Digestivas | BP31: 2 a 3 veces por semana | BQ31: Café | BS31: Sí | BT31: Sí | BU31: Siempre | BV31: No | BW31: No | BX31: Varón | BY31: 109.1 | BZ31: 1.87 | CA31: 31.2 | CB31: 84 | CC31: 152 | CD31: 96 | CE31: Sí | CF31: No | CG31: No | CH31: No | CI31: No | CJ31: Sí, primer grado | CK31: Sí | CL31: Sí | CM31: 07:44 | CN31: Mate | CO31: 15:30 | CP31: 160 | CQ31: 466 | CR31: Sí | CS31: 9 | CT31: Ligeramente elevado | CU31: 4 % | CV31: Sí | CW31: 3 | CX31: 1 | CY31: Bajo
A32: demo-31 | B32: A1-0031 | C32: 031-28-4612 | D32: 31 | E32: 28 | F32: 4612 | G32: 46301 | H32: 15:06 | J32: A | K32: 1 | L32: Encuestador A | M32: Puesto 1 | N32: Sí | O32: Sí | P32: 38 | Q32: Sí | R32: Sí | S32: Sí | T32: finalizado | U32: 2026-10-v2 | V32: 2026-10-06T15:00:00.000Z | W32: Argentina | Y32: Secundaria completa | Z32: Sí | AA32: Más de 5 | AB32: 3 | AC32: Español | AE32: Español | AG32: Argentina | AI32: Bueno | AJ32: 8 | AK32: Viaje interprovincial | AL32: Una vez al mes | AN32: Diariamente | AP32: Otro | AR32: Parcialmente conforme | AS32: Sí | AT32: 5.6 | AU32: Sí | AV32: En el camión al costado de la ruta | AX32: 4.5 | AY32: Varias veces por semana | AZ32: Café; Jugos artificiales | BB32: A veces | BC32: No | BD32: No | BE32: No | BF32: Ninguna | BG32: Ninguno | BH32: Solo cuando me siento mal | BI32: Sistema público; Otros (medicina tradicional, alternativa, etc.) | BJ32: Sí | BK32: Cervical | BL32: Ninguno | BN32: No tengo diagnóstico de enfermedad | BP32: Una vez a la semana | BQ32: Café | BS32: No | BT32: Sí | BU32: A veces | BV32: Sí | BW32: No | BX32: Varón | BY32: 73.9 | BZ32: 1.67 | CA32: 26.5 | CB32: 109 | CC32: 156 | CD32: 99 | CE32: Sí | CF32: No | CG32: No | CH32: No | CI32: No | CJ32: No | CK32: Sí | CL32: Sí | CM32: 07:31 | CN32: Mate | CO32: 12:30 | CP32: 175 | CQ32: 299 | CR32: Sí | CS32: 6 | CT32: Bajo | CU32: 1 % | CV32: Sí | CW32: 1 | CX32: 1 | CY32: Bajo
A33: demo-32 | B33: A1-0032 | C33: 032-66-4400 | D33: 32 | E33: 66 | F33: 4400 | G33: 46289 | H33: 16:04 | J33: A | K33: 1 | L33: Encuestador A | M33: Puesto 1 | N33: Sí | O33: Sí | P33: 39 | Q33: Sí | R33: Sí | S33: Sí | T33: finalizado | U33: 2026-10-v2 | V33: 2026-09-24T15:00:00.000Z | W33: Argentina | Y33: Secundaria incompleta | Z33: Sí | AA33: 5 | AB33: 5 | AC33: Español; Portugués | AE33: Español | AG33: Argentina | AI33: Regular | AJ33: 37 | AK33: Viaje interprovincial | AL33: Una vez a la semana | AN33: Diariamente | AP33: Empleado | AR33: Disconforme | AS33: Sí | AT33: 2.7 | AU33: Sí | AV33: En el camión al costado de la ruta; Paradores | AX33: 7.9 | AY33: Casi nunca | AZ33: Agua; Café | BB33: A veces | BC33: Sí | BD33: No | BE33: Sí | BF33: Obra social | BG33: Ninguno | BH33: Solo cuando me siento mal | BI33: Sistema privado | BJ33: Sí | BK33: Cervical | BL33: Medicamentos; Hierbas | BM33: Ibuprofeno | BN33: Musculoesqueléticos; Digestivas | BP33: Nunca | BQ33: Energizantes (Speed, Monster, Red Bull, etc.) | BS33: No | BT33: Sí | BU33: A veces | BV33: Sí | BW33: No | BX33: Varón | BY33: 99.3 | BZ33: 1.67 | CA33: 35.6 | CB33: 113 | CC33: 149 | CD33: 94 | CE33: No | CF33: Sí | CG33: No | CH33: No | CI33: No | CJ33: No | CK33: No | CL33: Sí | CM33: 07:32 | CN33: Mate | CO33: 13:30 | CP33: 146 | CQ33: 358 | CR33: Sí | CS33: 13 | CT33: Moderado | CU33: 17 % | CV33: Sí | CW33: 14 | CX33: 16 | CY33: Moderado
A34: demo-33 | B34: A1-0033 | C34: 033-26-4630 | D34: 33 | E34: 26 | F34: 4630 | G34: 46290 | H34: 15:08 | J34: A | K34: 1 | L34: Encuestador A | M34: Puesto 2 | N34: Sí | O34: Sí | P34: 38 | Q34: Sí | R34: Sí | S34: No | T34: finalizado | U34: 2026-10-v2 | V34: 2026-09-25T15:00:00.000Z | W34: Argentina | Y34: Terciario incompleto | Z34: Sí | AA34: 1 | AB34: 5 | AC34: Guaraní | AE34: Español | AG34: Argentina | AI34: Regular | AJ34: 6 | AK34: Viaje internacional | AL34: Una vez a la semana | AN34: Una vez a la semana | AP34: Empleado | AR34: Disconforme | AS34: Sí | AT34: 2.9 | AU34: Sí | AV34: Paradores; En el camión al costado de la ruta | AX34: 7.8 | AY34: Casi nunca | AZ34: Café | BB34: Nunca | BC34: No | BD34: No | BE34: No | BF34: Seguro de salud | BG34: Ninguno | BH34: Nunca | BI34: Sistema público; Otros (medicina tradicional, alternativa, etc.) | BJ34: No | BL34: Ninguno | BN34: Musculoesqueléticos; Digestivas | BP34: Nunca | BQ34: No | BS34: No | BT34: No | BU34: A veces | BV34: No | BW34: No | BX34: Varón | BY34: 72.5 | BZ34: 1.68 | CA34: 25.7 | CB34: 104 | CC34: 152 | CD34: 96 | CE34: No | CF34: No | CG34: No | CH34: No | CI34: No | CJ34: No | CK34: No | CL34: No | CR34: Sí | CS34: 8 | CT34: Ligeramente elevado | CU34: 4 % | CV34: Sí | CW34: -7 | CX34: <1 | CY34: Bajo
A35: demo-34 | B35: A1-0034 | C35: 034-37-4400 | D35: 34 | E35: 37 | F35: 4400 | G35: 46290 | H35: 14:01 | J35: A | K35: 1 | L35: Encuestador A | M35: Puesto 1 | N35: Sí | O35: Sí | P35: 38 | Q35: Sí | R35: Sí | S35: Sí | T35: finalizado | U35: 2026-10-v2 | V35: 2026-09-25T15:00:00.000Z | W35: Argentina | Y35: Secundaria completa | Z35: Sí | AA35: 4 | AB35: 5 | AC35: Portugués | AE35: Español | AG35: Argentina | AI35: Muy malo | AJ35: 15 | AK35: Viaje provincial (Jujuy) | AL35: Una vez a la semana | AN35: Diariamente | AP35: Dueño del camión | AR35: Disconforme | AS35: Sí | AT35: 8.3 | AU35: No | AV35: En el camión al costado de la ruta | AX35: 5.6 | AY35: Varias veces por semana | AZ35: Gaseosas; Mate | BB35: Nunca | BC35: No | BD35: No | BE35: Parcialmente | BF35: Obra social | BG35: Ninguno | BH35: Una vez al año | BI35: Sistema público; Otros (medicina tradicional, alternativa, etc.) | BJ35: Sí | BK35: Cervical | BL35: Ninguno | BN35: Musculoesqueléticos | BP35: Rara vez | BQ35: Yerba mate | BS35: No | BT35: Sí | BU35: Siempre | BV35: No | BW35: No | BX35: Varón | BY35: 69.9 | BZ35: 1.74 | CA35: 23.1 | CB35: 91 | CC35: 164 | CD35: 104 | CE35: No | CF35: Sí | CG35: No | CH35: Sí | CI35: No | CJ35: No | CK35: Sí | CL35: Sí | CM35: 07:47 | CN35: Mate | CO35: 14:30 | CP35: 172 | CQ35: 403 | CR35: Sí | CS35: 4 | CT35: Bajo | CU35: 1 % | CV35: Sí | CW35: 7 | CX35: 3 | CY35: Bajo
A36: demo-35 | B36: B1-0035 | C36: 234-60-4630 | D36: 234 | E36: 60 | F36: 4630 | G36: 46291 | H36: 15:00 | J36: B | K36: 1 | L36: Encuestador B | M36: Puesto 2 | N36: Sí | O36: Sí | P36: 38 | Q36: Sí | R36: Sí | S36: Sí | T36: finalizado | U36: 2026-10-v2 | V36: 2026-09-26T15:00:00.000Z | W36: Brasil | Y36: Primaria completa | Z36: Sí | AA36: 2 | AB36: 5 | AC36: Español | AE36: Español | AG36: Argentina | AI36: Bueno | AJ36: 32 | AK36: Viaje interprovincial | AL36: Quincenalmente | AN36: 2 veces por semana | AP36: Empleado | AR36: Conforme | AS36: Sí | AT36: 2.9 | AU36: Sí | AV36: En el camión al costado de la ruta | AX36: 4.7 | AY36: Todos los días | AZ36: Agua; Café | BB36: Sí, siempre | BC36: Algunas veces | BD36: No | BE36: No | BF36: Ninguna | BG36: Sistema público | BH36: Una vez al año | BI36: Sistema público; Otros (medicina tradicional, alternativa, etc.) | BJ36: Sí | BK36: Lumbar | BL36: Ninguno | BN36: Musculoesqueléticos; Digestivas | BP36: 2 a 3 veces por semana | BQ36: No | BS36: Sí | BT36: Sí | BU36: A veces | BV36: Sí | BW36: No | BX36: Varón | BY36: 78.3 | BZ36: 1.66 | CA36: 28.4 | CB36: 97 | CC36: 154 | CD36: 97 | CE36: Sí | CF36: No | CG36: No | CH36: No | CI36: Sí | CJ36: No | CK36: No | CL36: Sí | CM36: 07:23 | CN36: Mate | CO36: 13:30 | CP36: 106 | CQ36: 367 | CR36: Sí | CS36: 13 | CT36: Moderado | CU36: 17 % | CV36: Sí | CW36: 12 | CX36: 10 | CY36: Moderado
A37: demo-36 | B37: B1-0036 | C37: 235-51-4630 | D37: 235 | E37: 51 | F37: 4630 | G37: 46296 | H37: 15:03 | J37: B | K37: 1 | L37: Encuestador B | M37: Puesto 1 | N37: Sí | O37: Sí | P37: 38 | Q37: Sí | R37: Sí | S37: Sí | T37: finalizado | U37: 2026-10-v2 | V37: 2026-10-01T15:00:00.000Z | W37: Argentina | Y37: Universitario completo | Z37: Sí | AA37: 3 | AB37: 3 | AC37: Guaraní | AE37: Español | AG37: Argentina | AI37: Malo | AJ37: 25 | AK37: Viaje interprovincial | AL37: 2 veces por semana | AN37: 3 veces por semana | AP37: Dueño del camión | AR37: Disconforme | AS37: No | AT37: 3.5 | AU37: Sí | AV37: Estaciones de servicio | AX37: 6.6 | AY37: Todos los días | AZ37: Mate | BB37: Sí, siempre | BC37: Sí | BD37: No | BE37: Parcialmente | BF37: Seguro de salud | BG37: Sistema público | BH37: 2 veces al año | BI37: Sistema público | BJ37: Sí | BK37: Rodillas | BL37: Ninguno | BN37: Musculoesqueléticos; Digestivas | BP37: Nunca | BQ37: Café; Coca-Cola | BS37: Sí | BT37: No | BU37: Nunca | BV37: Sí | BW37: No | BX37: Varón | BY37: 79.7 | BZ37: 1.8 | CA37: 24.6 | CB37: 84 | CC37: 162 | CD37: 102 | CE37: No | CF37: Sí | CG37: No | CH37: No | CI37: No | CJ37: Sí, parientes lejanos | CK37: No | CL37: Sí | CM37: 07:13 | CN37: Mate | CO37: 13:30 | CP37: 79 | CQ37: 377 | CR37: Sí | CS37: 7 | CT37: Ligeramente elevado | CU37: 4 % | CV37: Sí | CW37: 8 | CX37: 4 | CY37: Bajo
